Workbook
Name IQ_CH: 110000
Name IQ_CQ: 5000
Name IQ_CY: 10000
Name IQ_DAILY: 500000
Name IQ_FH: 100000
Name IQ_FQ: 500
Name IQ_FY: 1000
Name IQ_LTM: 2000
Name IQ_MONTH: 15000
Name IQ_NTM: 6000
Name IQ_WEEK: 50000
Name IQ_YTD: 3000

Sheet Composição do Lucro
B1: Ação | C1: Ano | F1: 1996 | G1: 1997 | H1: 1998 | I1: 1999 | J1: 2000 | K1: 2001 | L1: 2002 | M1: 2003 | N1: 2004 | O1: 2005 | P1: 2006 | Q1: 2007 | R1: 2008 | S1: 2009 | T1: 2010 | U1: 2011 | V1: 2012 | W1: 2013 | X1: 2014 | Y1: 2015 | Z1: 2016 | AA1: 2017 | AB1: 2018 | AC1: 2019 | AD1: 2020 | AE1: 2021 | AF1: 2022 | AG1: 2023 | AH1: 2024
B2: {=_xlfn.VSTACK(VALE3:BBSE3!L17:AR17)} -> Vale ON | C2: Lucro Líquido Contábil | D2: 0 | E2: 0 | F2: 516990 | G2: 756000 | H2: 1029400 | I2: 1251199 | J2: 2132657 | K2: 3050710 | L2: 2043256 | M2: 4508850 | N2: 6459519 | O2: 10442986 | P2: 13431005 | Q2: 20005562 | R2: 21279629 | S2: 10248950 | T2: 30070051 | U2: 37813723 | V2: 9733696 | W2: 115091 | X2: 954384 | Y2: -44212187 | Z2: 13311455 | AA2: 17627201 | AB2: 25656526 | AC2: -6671445 | AD2: 26712713 | AE2: 121228000 | AF2: 18788000 | AG2: 7049000 | AH2: 44938000
B3: Petrobras PN | C3: Lucro Líquido Contábil | D3: 0 | E3: 0 | F3: 668609 | G3: 1510983 | H3: 1388629 | I3: 1756652 | J3: 9942392 | K3: 9867038 | L3: 8097791 | M3: 17794669 | N3: 17860754 | O3: 23724723 | P3: 25918920 | Q3: 21511789 | R3: 32987792 | S3: 28981708 | T3: 35189366 | U3: 33313097 | V3: 21182442 | W3: 23570367 | X3: -21587000 | Y3: -34836000 | Z3: -14824000 | AA3: -446000 | AB3: 25779000 | AC3: 40137000 | AD3: 7108000 | AE3: 106668000 | AF3: 36623000 | AG3: 2962000 | AH3: 130169000
B4: ItauUnibanco PN | C4: Lucro Líquido Contábil | D4: 0 | E4: 0 | F4: 592097 | G4: 720780 | H4: 879921 | I4: 1869363 | J4: 1840568 | K4: 2389468 | L4: 2376723 | M4: 3151820 | N4: 3775616 | O4: 5251334 | P4: 4308927 | Q4: 8473604 | R4: 7803483 | S4: 10066608 | T4: 13322963 | U4: 14620621 | V4: 13593940 | W4: 15695749 | X4: 20241564 | Y4: 23359834 | Z4: 21639125 | AA4: 23964551 | AB4: 24977422 | AC4: 26582639 | AD4: 18909000 | AE4: 24988000 | AF4: 29207000 | AG4: 15564000 | AH4: 11630000
B5: Petrobras ON | C5: Lucro Líquido Contábil | D5: 0 | E5: 0 | F5: 668609 | G5: 1510983 | H5: 1388629 | I5: 1756652 | J5: 9942392 | K5: 9867038 | L5: 8097791 | M5: 17794669 | N5: 17860754 | O5: 23724723 | P5: 25918920 | Q5: 21511789 | R5: 32987792 | S5: 28981708 | T5: 35189366 | U5: 33313097 | V5: 21182442 | W5: 23570367 | X5: -21587000 | Y5: -34836000 | Z5: -14824000 | AA5: -446000 | AB5: 25779000 | AC5: 40137000 | AD5: 7108000 | AE5: 106668000 | AF5: 36623000 | AG5: 2962000 | AH5: 130169000
B6: Eletrobras ON | C6: Lucro Líquido Contábil | D6: 0 | E6: 0 | F6: 2393485 | G6: 3378212 | H6: 1994178 | I6: 580589 | J6: 2455813 | K6: 3251336 | L6: 1100340 | M6: 323125 | N6: 1293314 | O6: 974589 | P6: 1161318 | Q6: 1547857 | R6: 6136497 | S6: 170526 | T6: 2247913 | U6: 3732565 | V6: -6878915 | W6: -6286663 | X6: -3031055 | Y6: -14441607 | Z6: 3425899 | AA6: -1763805 | AB6: 13262378 | AC6: 10697124 | AD6: 6338688 | AE6: 5646141 | AF6: 3635377 | AG6: 79980581 | AH6: 34739705
B7: Bradesco PN | C7: Lucro Líquido Contábil | D7: 0 | E7: 0 | F7: 824493 | G7: 830512 | H7: 1012420 | I7: 1104806 | J7: 1740165 | K7: 2170130 | L7: 2022588 | M7: 2306339 | N7: 3060151 | O7: 5514074 | P7: 5054040 | Q7: 8009724 | R7: 7620238 | S7: 8012282 | T7: 10021673 | U7: 11028266 | V7: 11381244 | W7: 12011028 | X7: 15088818 | Y7: 17189635 | Z7: 15083578 | AA7: 14657755 | AB7: 19084953 | AC7: 22582615 | AD7: 16546577 | AE7: 21945688 | AF7: 21223264 | AG7: 12257722 | AH7: 11971122
B8: B3 ON | C8: Lucro Líquido Contábil | D8: 0 | E8: 0 | F8: 0 | G8: 0 | H8: 0 | I8: 0 | J8: 0 | K8: 0 | L8: 0 | M8: 0 | N8: 0 | O8: 0 | P8: 0 | Q8: 0 | R8: 645596 | S8: 881050 | T8: 1144561 | U8: 1047999 | V8: 1074290 | W8: 1081516 | X8: 977053 | Y8: 2202238 | Z8: 1446263 | AA8: 1296240 | AB8: 2087444 | AC8: 2714166 | AD8: 4152304 | AE8: 4717097 | AF8: 4226057 | AG8: 2097613 | AH8: 920622
B9: Brasil ON | C9: Lucro Líquido Contábil | D9: 0 | E9: 0 | F9: -7525817 | G9: 573819 | H9: 869893 | I9: 843050 | J9: 974211 | K9: 1081952 | L9: 2027676 | M9: 2380982 | N9: 3024006 | O9: 4153602 | P9: 6043777 | Q9: 5058119 | R9: 8802869 | S9: 10147522 | T9: 11703165 | U9: 12125990 | V9: 12205120 | W9: 15757937 | X9: 11245814 | Y9: 14399559 | Z9: 8033556 | AA9: 11010776 | AB9: 12862026 | AC9: 18162067 | AD9: 12697385 | AE9: 19710402 | AF9: 31112242 | AG9: 11014625 | AH9: 8825918
B10: Ambev S/A ON | C10: Lucro Líquido Contábil | D10: 0 | E10: 0 | F10: 324894 | G10: 456323 | H10: 329098 | I10: -310682 | J10: 470182 | K10: 784568 | L10: 1510313 | M10: 1411570 | N10: 1161533 | O10: 1545728 | P10: 2806256 | Q10: 2816407 | R10: 3059478 | S10: 5986050 | T10: 7561383 | U10: 8640976 | V10: 10508066 | W10: 9534969 | X10: 12065512 | Y10: 12423771 | Z10: 12546610 | AA10: 7331968 | AB10: 11024678 | AC10: 11779965 | AD10: 11379394 | AE10: 12670968 | AF10: 14457900 | AG10: 9222200 | AH10: 30055700
B11: Localiza ON | C11: Lucro Líquido Contábil | D11: 0 | E11: 0 | F11: 0 | G11: 0 | H11: 0 | I11: 19931 | J11: 44655 | K11: 42981 | L11: 0 | M11: 0 | N11: 102343 | O11: 96720 | P11: 118411 | Q11: 156992 | R11: 136517 | S11: 102030 | T11: 255892 | U11: 291642 | V11: 240936 | W11: 384344 | X11: 410589 | Y11: 402427 | Z11: 409315 | AA11: 505676 | AB11: 659208 | AC11: 833938 | AD11: 1048180 | AE11: 2043677 | AF11: 1844306 | AG11: 373785 | AH11: 43020498
B12: Itausa PN | C12: Lucro Líquido Contábil | D12: 0 | E12: 0 | F12: 295722 | G12: 465634 | H12: 468922 | I12: 951105 | J12: 882455 | K12: 1182829 | L12: 1537264 | M12: 1561263 | N12: 1962392 | O12: 2297173 | P12: 4485631 | Q12: 3988482 | R12: 2699680 | S12: 3930204 | T12: 4417000 | U12: 4837000 | V12: 4539000 | W12: 5698000 | X12: 7911000 | Y12: 8868000 | Z12: 8211000 | AA12: 8403000 | AB12: 9436000 | AC12: 10312000 | AD12: 7056000 | AE12: 12200000 | AF12: 13674000 | AG12: 450000 | AH12: 4620000
B13: Weg ON | C13: Lucro Líquido Contábil | D13: 0 | E13: 0 | F13: 40660 | G13: 58494 | H13: 97531 | I13: 81997 | J13: 125426 | K13: 175683 | L13: 220326 | M13: 307809 | N13: 402654 | O13: 374812 | P13: 502831 | Q13: 574984 | R13: 560401 | S13: 548392 | T13: 519782 | U13: 586936 | V13: 655979 | W13: 843467 | X13: 954726 | Y13: 1156065 | Z13: 1117624 | AA13: 1142149 | AB13: 1338319 | AC13: 1614581 | AD13: 2340873 | AE13: 3585947 | AF13: 4208084 | AG13: 238820 | AH13: 6282653
B14: Btgp Banco UNT | C14: Lucro Líquido Contábil | D14: 0 | E14: 0 | F14: 0 | G14: 0 | H14: 0 | I14: 0 | J14: 0 | K14: 0 | L14: 0 | M14: 0 | N14: 0 | O14: 0 | P14: 0 | Q14: 0 | R14: 0 | S14: 0 | T14: 0 | U14: 1477020 | V14: 2061237 | W14: 2669689 | X14: 3369246 | Y14: 5623498 | Z14: 3408583 | AA14: 2383863 | AB14: 2360784 | AC14: 3828312 | AD14: 3976382 | AE14: 6342155 | AF14: 7841837 | AG14: 4703387 | AH14: 508618
... B25: BBSeguridade ON | C25: Lucro Líquido Contábil | D25: 0 | E25: 0 | F25: 0 | G25: 0 | H25: 0 | I25: 0 | J25: 0 | K25: 0 | L25: 0 | M25: 0 | N25: 0 | O25: 0 | P25: 0 | Q25: 0 | R25: 0 | S25: 0 | T25: 0 | U25: 0 | V25: 1240112 | W25: 2473752 | X25: 3456683 | Y25: 4207432 | Z25: 4013852 | AA25: 4049245 | AB25: 3539553 | AC25: 6658781 | AD25: 3850771 | AE25: 3933217 | AF25: 6196415 | AG25: 4021 | AH25: 47
C26: Média | F26: =+ AVERAGEIF(F2:F25, "<>",F2:F25) -> -47044.083 | G26: =+ AVERAGEIF(G2:G25, "<>",G2:G25) -> 434741.62 | H26: =+ AVERAGEIF(H2:H25, "<>",H2:H25) -> 412135.42 | I26: =+ AVERAGEIF(I2:I25, "<>",I2:I25) -> 431472.25 | J26: =+ AVERAGEIF(J2:J25, "<>",J2:J25) -> 1327077.5 | K26: =+ AVERAGEIF(K2:K25, "<>",K2:K25) -> 1464753.6 | L26: =+ AVERAGEIF(L2:L25, "<>",L2:L25) -> 1282958 | M26: =+ AVERAGEIF(M2:M25, "<>",M2:M25) -> 2230056.8 | ... AH26: =+ AVERAGEIF(AH2:AH25, "<>",AH2:AH25) -> 28154855
B28: Ação | C28: Ano | F28: 1996 | G28: 1997 | H28: 1998 | I28: 1999 | J28: 2000 | K28: 2001 | L28: 2002 | M28: 2003 | N28: 2004 | O28: 2005 | P28: 2006 | Q28: 2007 | R28: 2008 | S28: 2009 | T28: 2010 | U28: 2011 | V28: 2012 | W28: 2013 | X28: 2014 | Y28: 2015 | Z28: 2016 | AA28: 2017 | AB28: 2018 | AC28: 2019 | AD28: 2020 | AE28: 2021 | AF28: 2022 | AG28: 2023 | AH28: 2024
B29: {=_xlfn.VSTACK(VALE3:BBSE3!L18:AR18)} -> Vale ON | C29: Lucro com efeitos inflacionário | D29: 0 | E29: 0 | F29: 460832.27 | G29: 799616.79 | H29: 981722.87 | I29: 1219912.1 | J29: 2085365.9 | K29: 3017182.6 | L29: 2100100.1 | M29: 4626686.3 | N29: 6528511 | O29: 10365617 | P29: 12681333 | Q29: 20939581 | R29: 21884997 | S29: 9779218.8 | T29: 30350972 | U29: 38379967 | V29: 7011931.4 | W29: 241731.64 | X29: 662998.27 | Y29: -61966748 | Z29: -1286914.5 | AA29: 7927394 | AB29: 21964982 | AC29: -11518410 | AD29: 13509847 | AE29: 99027367 | AF29: -1522787.6 | AG29: -5659998.7 | AH29: 42284408
B30: Petrobras PN | C30: Lucro com efeitos inflacionário | D30: 0 | E30: 0 | F30: -49974.566 | G30: 1100452.6 | H30: 1209381.8 | I30: 1693773.8 | J30: 9914373.6 | K30: 9553335.6 | L30: 8083685 | M30: 18208782 | N30: 18103105 | O30: 23669386 | P30: 24430457 | Q30: 20800483 | R30: 33381743 | S30: 29061857 | T30: 36123458 | U30: 34548054 | V30: 15531798 | W30: 28407669 | X30: -22227439 | Y30: -69854826 | Z30: -44414548 | AA30: -21568168 | AB30: 24573099 | AC30: 40979880 | AD30: -22167203 | AE30: 61413517 | AF30: -10595881 | AG30: -31686021 | AH30: 1.054983e+08
B31: ItauUnibanco PN | C31: Lucro com efeitos inflacionário | D31: 0 | E31: 0 | F31: 433191.59 | G31: 563899.83 | H31: 757785.18 | I31: 1501793.7 | J31: 1437580.4 | K31: 1815015 | L31: 1362931.1 | M31: 1971967.3 | N31: 2426611.5 | O31: 3892397.7 | P31: 3010221.8 | Q31: 6647845.9 | R31: 5091211.5 | S31: 7303411.6 | T31: 9394796.9 | U31: 9655056.1 | V31: 8423401.7 | W31: 10092576 | X31: 13463094 | Y31: 10796385 | Z31: 12454176 | AA31: 18030186 | AB31: 17981225 | AC31: 18790822 | AD31: 9864945.9 | AE31: 9077016.1 | AF31: 19024591 | AG31: 5533370 | AH31: 12210220
B32: Petrobras ON | C32: Lucro com efeitos inflacionário | D32: 0 | E32: 0 | F32: -49974.566 | G32: 1100452.6 | H32: 1209381.8 | I32: 1693773.8 | J32: 9914373.6 | K32: 9553335.6 | L32: 8083685 | M32: 18208782 | N32: 18103105 | O32: 23669386 | P32: 24430457 | Q32: 20800483 | R32: 33381743 | S32: 29061857 | T32: 36123458 | U32: 34548054 | V32: 15531798 | W32: 28407669 | X32: -22227439 | Y32: -69854826 | Z32: -44414548 | AA32: -21568168 | AB32: 24573099 | AC32: 40979880 | AD32: -22167203 | AE32: 61413517 | AF32: -10595881 | AG32: -31686021 | AH32: 1.054983e+08
B33: Eletrobras ON | C33: Lucro com efeitos inflacionário | D33: 0 | E33: 0 | F33: 1552307.1 | G33: 2661569.8 | H33: 648935.61 | I33: -460458.37 | J33: 18022.184 | K33: 229715.95 | L33: -1804703.8 | M33: -5570398.7 | N33: -7423552.9 | O33: -10436618 | P33: -12846016 | Q33: -12774884 | R33: -8560667.9 | S33: -17215346 | T33: -15229385 | U33: -15433956 | V33: -28809047 | W33: -29781653 | X33: -26120143 | Y33: -34392403 | Z33: -29241198 | AA33: -45297483 | AB33: -27386150 | AC33: -28465307 | AD33: -35388426 | AE33: -12928769 | AF33: -40570362 | AG33: 25344231 | AH33: -14919214
B34: Bradesco PN | C34: Lucro com efeitos inflacionário | D34: 0 | E34: 0 | F34: 478452.64 | G34: 588434.82 | H34: 887490.83 | I34: 604326.36 | J34: 1303664.3 | K34: 1525427.9 | L34: 877940.86 | M34: 1126186.1 | N34: 1780727.6 | O34: 4204512.4 | P34: 3898048 | Q34: 6346399.8 | R34: 5332723.1 | S34: 5854664.9 | T34: 6920050 | U34: 7205003.9 | V34: 7072001.6 | W34: 7154386.1 | X34: 9461978.9 | Y34: 6938389.1 | Z34: 7644549.5 | AA34: 9857370 | AB34: 13304615 | AC34: 15701875 | AD34: 8118219.9 | AE34: 6028125.8 | AF34: 11413073 | AG34: 3216591.6 | AH34: 11423103
B35: B3 ON | C35: Lucro com efeitos inflacionário | D35: 0 | E35: 0 | F35: 0 | G35: 0 | H35: 0 | I35: 0 | J35: 0 | K35: 0 | L35: 0 | M35: 0 | N35: 4865.824 | O35: -41099.797 | P35: -24338.694 | Q35: -46288.158 | R35: 41665.051 | S35: 48500.729 | T35: 482272.01 | U35: 813379.87 | V35: -80117.819 | W35: 727710.04 | X35: -374071.16 | Y35: -47065.817 | Z35: -255293.19 | AA35: 380571.58 | AB35: 1671302.7 | AC35: 975244.66 | AD35: 2287400.5 | AE35: 1831823.1 | AF35: 1630722.8 | AG35: -112487.68 | AH35: 2043008.5
B36: Brasil ON | C36: Lucro com efeitos inflacionário | D36: 0 | E36: 0 | F36: -7753050.7 | G36: 335090.71 | H36: 732898.72 | I36: 361151.77 | J36: 544945.48 | K36: 489737.82 | L36: 1062630.5 | M36: 1330956.8 | N36: 1822639.6 | O36: 2908685.4 | P36: 4871826.6 | Q36: 3531366.9 | R36: 6697109.6 | S36: 7996728.1 | T36: 8535935.2 | U36: 7989962.1 | V36: 7775197 | W36: 10908142 | X36: 5585409 | Y36: 4443110.4 | Z36: 767369.96 | AA36: 6008796.4 | AB36: 7137666.3 | AC36: 11755063 | AD36: 5030649.1 | AE36: 5288378.7 | AF36: 20497989 | AG36: 726010.82 | AH36: 2111243.9
B37: Ambev S/A ON | C37: Lucro com efeitos inflacionário | D37: 0 | E37: 0 | F37: 372894.09 | G37: 461556.17 | H37: 294239.1 | I37: -233478.58 | J37: 433712.76 | K37: 637895.94 | L37: 1255950.1 | M37: 1052245.4 | N37: 302532.13 | O37: 273213.25 | P37: 1706897.1 | Q37: 1573788.6 | R37: 1694698.6 | S37: 4555020.3 | T37: 6274311.6 | U37: 7711281.1 | V37: 7971653 | W37: 8018693.7 | X37: 7973149.1 | Y37: 5499879.9 | Z37: 6385710.5 | AA37: 2436684.7 | AB37: 7716483 | AC37: 6259215.6 | AD37: 3998394.9 | AE37: 2137752.9 | AF37: 5061906.8 | AG37: 54929.13 | AH37: 38931585
B38: Localiza ON | C38: Lucro com efeitos inflacionário | D38: 0 | E38: 0 | F38: 0 | G38: 0 | H38: 0 | I38: 19931 | J38: 36278.851 | K38: 30120.416 | L38: -22526.365 | M38: 0 | N38: 107436.03 | O38: 119360.91 | P38: 124865 | Q38: 189259.94 | R38: 186509.47 | S38: 133810.69 | T38: 315184.55 | U38: 363639.04 | V38: 262743.6 | W38: 408219.39 | X38: 422345.01 | Y38: 132097.91 | Z38: 186888.19 | AA38: 330217.55 | AB38: 735371.62 | AC38: 897834.07 | AD38: 561951.43 | AE38: 1343529.1 | AF38: 1572069.1 | AG38: -281418.25 | AH38: 42814603
B39: Itausa PN | C39: Lucro com efeitos inflacionário | D39: 0 | E39: 0 | F39: 360787.74 | G39: 434203.43 | H39: 391794.7 | I39: 845884.14 | J39: 695618.2 | K39: 901634.75 | L39: 1027600.8 | M39: 871716.35 | N39: 1124340.8 | O39: 1383351.1 | P39: 3549992.9 | Q39: 2819515 | R39: 1335975.5 | S39: 2589693.1 | T39: 2638362.8 | U39: 2581866.4 | V39: 2005070.5 | W39: 2959748 | X39: 4666318 | Y39: 3342797 | Z39: 3378012.7 | AA39: 4578133.4 | AB39: 5178290 | AC39: 7982098.2 | AD39: 3900002.1 | AE39: 4018623 | AF39: 6730599 | AG39: -6675454.7 | AH39: 1135139.8
B40: Weg ON | C40: Lucro com efeitos inflacionário | D40: 0 | E40: 0 | F40: 30528.952 | G40: 52041.106 | H40: 93462.198 | I40: 63075.462 | J40: 107148.43 | K40: 147451.01 | L40: 166769.82 | M40: 254051.19 | N40: 342945.21 | O40: 313503.34 | P40: 450328.78 | Q40: 504955.35 | R40: 469841.78 | S40: 463143.59 | T40: 420213.33 | U40: 481320.92 | V40: 510546.26 | W40: 694017.98 | X40: 725982.5 | Y40: 461544.24 | Z40: 582796.75 | AA40: 807356.64 | AB40: 1068691.4 | AC40: 1230839.6 | AD40: 1691014.7 | AE40: 2181302.4 | AF40: 3253031.9 | AG40: -651140.52 | AH40: 7152059.8
B41: Btgp Banco UNT | C41: Lucro com efeitos inflacionário | D41: 0 | E41: 0 | F41: 0 | G41: 0 | H41: 0 | I41: 0 | J41: 0 | K41: 0 | L41: 0 | M41: 0 | N41: 0 | O41: 0 | P41: 0 | Q41: -52466.749 | R41: -225118.89 | S41: -151947.47 | T41: -190988.7 | U41: 1092724.5 | V41: 1581992.5 | W41: 2018793 | X41: 2514665.9 | Y41: 3774215.2 | Z41: 2184971.4 | AA41: 1929781.8 | AB41: 1661423.6 | AC41: 2963054.3 | AD41: 2821526.2 | AE41: 2979370.4 | AF41: 5832682.5 | AG41: 2942191.7 | AH41: -1027296.3
... B52: BBSeguridade ON | C52: Lucro com efeitos inflacionário | D52: 0 | E52: 0 | F52: 0 | G52: 0 | H52: 0 | I52: 0 | J52: 0 | K52: 0 | L52: 0 | M52: 0 | N52: 0 | O52: 0 | P52: 0 | Q52: 0 | R52: 0 | S52: 0 | T52: 0 | U52: -268574.99 | V52: 929013.54 | W52: 2102023.4 | X52: 3325464.8 | Y52: 3915509.1 | Z52: 3491649.1 | AA52: 3809636.5 | AB52: 3244846.3 | AC52: 6727479.5 | AD52: 3784252.1 | AE52: 2915004.8 | AF52: 5868532.1 | AG52: -327332.83 | AH52: 2282552.7
C53: Média | F53: =+ AVERAGEIF(F29:F52, "<>",F29:F52) -> -164611.94 | G53: =+ AVERAGEIF(G29:G52, "<>",G29:G52) -> 345973.59 | H53: =+ AVERAGEIF(H29:H52, "<>",H29:H52) -> 316561.47 | I53: =+ AVERAGEIF(I29:I52, "<>",I29:I52) -> 322477.89 | J53: =+ AVERAGEIF(J29:J52, "<>",J29:J52) -> 1154584.3 | K53: =+ AVERAGEIF(K29:K52, "<>",K29:K52) -> 1215802.1 | L53: =+ AVERAGEIF(L29:L52, "<>",L29:L52) -> 1008691 | M53: =+ AVERAGEIF(M29:M52, "<>",M29:M52) -> 1837516.4 | ... AH53: =+ AVERAGEIF(AH29:AH52, "<>",AH29:AH52) -> 23678529
C57: =C1 -> Ano | E57: 1995 | F57: 1996 | G57: 1997 | H57: 1998 | I57: 1999 | J57: 2000 | K57: 2001 | L57: 2002 | M57: 2003 | N57: 2004 | O57: 2005 | P57: 2006 | Q57: 2007 | R57: 2008 | S57: 2009 | T57: 2010 | U57: 2011 | V57: 2012 | W57: 2013 | X57: 2014 | Y57: 2015 | Z57: 2016 | AA57: 2017 | AB57: 2018 | AC57: 2019 | AD57: 2020 | AE57: 2021 | AF57: 2022 | AG57: 2023 | AH57: 2024
C58: =+C25 -> Lucro Líquido Contábil | F58: =+F26 -> -47044.083 | G58: =+G26 -> 434741.62 | H58: =+H26 -> 412135.42 | I58: =+I26 -> 431472.25 | J58: =+J26 -> 1327077.5 | K58: =+K26 -> 1464753.6 | L58: =+L26 -> 1282958 | M58: =+M26 -> 2230056.8 | ... AH58: =+AH26 -> 28154855
C59: =+C52 -> Lucro com efeitos inflacionário | F59: =+F53 -> -164611.94 | G59: =+G53 -> 345973.59 | H59: =+H53 -> 316561.47 | I59: =+I53 -> 322477.89 | J59: =+J53 -> 1154584.3 | K59: =+K53 -> 1215802.1 | L59: =+L53 -> 1008691 | M59: =+M53 -> 1837516.4 | ... AH59: =+AH53 -> 23678529
C60: Perda Inflacionária | F60: =+F58-F59 -> 117567.85 | G60: =+G58-G59 -> 88768.036 | H60: =+H58-H59 -> 95573.951 | I60: =+I58-I59 -> 108994.36 | J60: =+J58-J59 -> 172493.17 | K60: =+K58-K59 -> 248951.49 | L60: =+L58-L59 -> 274267.08 | M60: =+M58-M59 -> 392540.4 | ... AH60: =+AH58-AH59 -> 4476326.4
C62: Ajustando a uma mesma "moeda" | E62: 4.706785 | F62: 4.2088217 | G62: 3.9504103 | H62: 3.8695753 | I62: 3.4699608 | J62: 3.218138 | K62: 2.9176539 | L62: 2.4814307 | M62: 2.1852065 | N62: 1.9602291 | O62: 1.8008601 | P62: 1.7155906 | Q62: 1.5996463 | R62: 1.4548124 | S62: 1.3533817 | T62: 1.222058 | U62: 1.0864395 | V62: 0.97131469 | W62: 0.8613112 | X62: 0.74918823 | Y62: 0.58054417 | Z62: 0.48701117 | AA62: 0.44440133 | AB62: 0.39219405 | AC62: 0.33466978 | AD62: 0.27695157 | AE62: 0.16023221 | AF62: 0.09673146 | AG62: 0.0483 | AH62: 0
C64: =+C57 -> Ano | E64: 1995 | F64: 1996 | G64: 1997 | H64: 1998 | I64: 1999 | J64: 2000 | K64: 2001 | L64: 2002 | M64: 2003 | N64: 2004 | O64: 2005 | P64: 2006 | Q64: 2007 | R64: 2008 | S64: 2009 | T64: 2010 | U64: 2011 | V64: 2012 | W64: 2013 | X64: 2014 | Y64: 2015 | Z64: 2016 | AA64: 2017 | AB64: 2018 | AC64: 2019 | AD64: 2020 | AE64: 2021 | AF64: 2022 | AG64: 2023 | AH64: 2024
C65: =+C58 -> Lucro Líquido Contábil | F65: =+F58*(100%+F62) -> -245044.24 | G65: =+G58*(100%+G62) -> 2152149.4 | H65: =+H58*(100%+H62) -> 2006924.5 | I65: =+I58*(100%+I62) -> 1928664.1 | J65: =+J58*(100%+J62) -> 5597795.8 | K65: =+K58*(100%+K62) -> 5738397.6 | L65: =+L58*(100%+L62) -> 4466529.5 | M65: =+M58*(100%+M62) -> 7103191.3 | ... AH65: =+AH58*(100%+AH62) -> 28154855
C66: =+C59 -> Lucro com efeitos inflacionário | F66: =+F59*(100%+F62) -> -857434.23 | G66: =+G59*(100%+G62) -> 1712711.2 | H66: =+H59*(100%+H62) -> 1541519.9 | I66: =+I59*(100%+I62) -> 1441463.5 | J66: =+J59*(100%+J62) -> 4870195.8 | K66: =+K59*(100%+K62) -> 4763091.9 | L66: =+L59*(100%+L62) -> 3511687.6 | M66: =+M59*(100%+M62) -> 5852869.1 | ... AH66: =+AH59*(100%+AH62) -> 23678529
...

Sheet Valor de Mercado e PL Corrigido
B1: Ação | C1: Ano | F1: 1996 | G1: 1997 | H1: 1998 | I1: 1999 | J1: 2000 | K1: 2001 | L1: 2002 | M1: 2003 | N1: 2004 | O1: 2005 | P1: 2006 | Q1: 2007 | R1: 2008 | S1: 2009 | T1: 2010 | U1: 2011 | V1: 2012 | W1: 2013 | X1: 2014 | Y1: 2015 | Z1: 2016 | AA1: 2017 | AB1: 2018 | AC1: 2019 | AD1: 2020 | AE1: 2021 | AF1: 2022 | AG1: 2023 | AH1: 2024
B2: {=_xlfn.VSTACK(VALE3:BBSE3!L22:AR22)} -> Vale ON | C2: PL | D2: 0 | E2: 0 | F2: 10228870 | G2: 9472000 | H2: 9712283 | I2: 10502002 | J2: 10565590 | K2: 11766563 | L2: 12750519 | M2: 14939574 | N2: 18169333 | O2: 24052131 | P2: 39098760 | Q2: 57029465 | R2: 96274640 | S2: 95736974 | T2: 112118004 | U2: 143475398 | V2: 152388190 | W2: 148345807 | X2: 146414683 | Y2: 131160217 | Z2: 127240523 | AA2: 143757534 | AB2: 170402626 | AC2: 161480300 | AD2: 185784979 | AE2: 192403000 | AF2: 187112000 | AG2: 187112000 | AH2: 187112000
B3: Petrobras PN | C3: PL | D3: 0 | E3: 0 | F3: 19975136 | G3: 21055416 | H3: 21734616 | I3: 10502002 | J3: 10565590 | K3: 28966503 | L3: 34324906 | M3: 49367329 | N3: 62271562 | O3: 78785236 | P3: 97530648 | Q3: 113854127 | R3: 138365282 | S3: 159464599 | T3: 306765182 | U3: 329838881 | V3: 343079673 | W3: 347939893 | X3: 308848000 | Y3: 254731000 | Z3: 250230000 | AA3: 263985000 | AB3: 277225000 | AC3: 295541000 | AD3: 308410000 | AE3: 387329000 | AF3: 362594000 | AG3: 362594000 | AH3: 362594000
B4: ItauUnibanco PN | C4: PL | D4: 0 | E4: 0 | F4: 3842455 | G4: 4197522 | H4: 4651335 | I4: 10502002 | J4: 10565590 | K4: 7578222 | L4: 9036410 | M4: 11879208 | N4: 13971082 | O4: 15559656 | P4: 23564471 | Q4: 28969086 | R4: 43664036 | S4: 50683423 | T4: 60878545 | U4: 71347333 | V4: 74219609 | W4: 81024484 | X4: 95847713 | Y4: 106462440 | Z4: 115590426 | AA4: 126923600 | AB4: 131756574 | AC4: 131987401 | AD4: 136593000 | AE4: 144554000 | AF4: 160925000 | AG4: 160925000 | AH4: 160925000
B5: Petrobras ON | C5: PL | D5: 0 | E5: 0 | F5: 19975136 | G5: 21055416 | H5: 21734616 | I5: 10502002 | J5: 10565590 | K5: 28966503 | L5: 34324906 | M5: 49367329 | N5: 62271562 | O5: 78785236 | P5: 97530648 | Q5: 113854127 | R5: 138365282 | S5: 159464599 | T5: 306765182 | U5: 329838881 | V5: 343079673 | W5: 347939893 | X5: 308848000 | Y5: 254731000 | Z5: 250230000 | AA5: 263985000 | AB5: 277225000 | AC5: 295541000 | AD5: 308410000 | AE5: 387329000 | AF5: 362594000 | AG5: 362594000 | AH5: 362594000
B6: Eletrobras ON | C6: PL | D6: 0 | E6: 0 | F6: 59644584 | G6: 61646875 | H6: 59995657 | I6: 10502002 | J6: 10565590 | K6: 64285524 | L6: 66550862 | M6: 67837732 | N6: 69873809 | O6: 75714890 | P6: 77835788 | Q6: 79963236 | R6: 85618361 | S6: 76091785 | T6: 70304115 | U6: 76843509 | V6: 67083945 | W6: 60493710 | X6: 56539551 | Y6: 42092014 | Z6: 44203470 | AA6: 42339377 | AB6: 55542906 | AC6: 70906801 | AD6: 73478307 | AE6: 76121204 | AF6: 110504796 | AG6: 110504796 | AH6: 110504796
B7: Bradesco PN | C7: PL | D7: 0 | E7: 0 | F7: 5460211 | G7: 5572745 | H7: 6320999 | I7: 10502002 | J7: 10565590 | K7: 9767946 | L7: 10845729 | M7: 13546880 | N7: 15214646 | O7: 19409274 | P7: 24636362 | Q7: 30357344 | R7: 34256544 | S7: 41753751 | T7: 48042850 | U7: 55581664 | V7: 70047459 | W7: 70939802 | X7: 81508250 | Y7: 88906644 | Z7: 100442413 | AA7: 110457476 | AB7: 121120869 | AC7: 133723221 | AD7: 143702640 | AE7: 147121011 | AF7: 154263000 | AG7: 154263000 | AH7: 154263000
B8: B3 ON | C8: PL | D8: 0 | E8: 0 | F8: 0 | G8: 0 | H8: 0 | I8: 10502002 | J8: 10565590 | K8: 0 | L8: 0 | M8: 0 | N8: 819128 | O8: 857655 | P8: 1062079 | Q8: 1353629 | R8: 19291724 | S8: 19709749 | T8: 19402765 | U8: 19241000 | V8: 19397918 | W8: 19284229 | X8: 18979509 | Y8: 18342099 | Z8: 19066470 | AA8: 24299694 | AB8: 25032969 | AC8: 25388001 | AD8: 24509951 | AE8: 22407905 | AF8: 20271137 | AG8: 20271137 | AH8: 20271137
B9: Brasil ON | C9: PL | D9: 0 | E9: 0 | F9: 5592213 | G9: 6003033 | H9: 6629873 | I9: 10502002 | J9: 10565590 | K9: 8747353 | L9: 9197065 | M9: 12171798 | N9: 14105696 | O9: 16849764 | P9: 20758158 | Q9: 24262096 | R9: 29937250 | S9: 36119265 | T9: 50440636 | U9: 57972442 | V9: 65495798 | W9: 69526297 | X9: 77519742 | Y9: 78408095 | Z9: 87193752 | AA9: 98723402 | AB9: 102252882 | AC9: 106661238 | AD9: 124567652 | AE9: 141995018 | AF9: 160278681 | AG9: 160278681 | AH9: 160278681
B10: Ambev S/A ON | C10: PL | D10: 0 | E10: 0 | F10: 1263852 | G10: 1350303 | H10: 1428416 | I10: 10502002 | J10: 10565590 | K10: 3363437 | L10: 4129647 | M10: 4308217 | N10: 16995979 | O10: 19867339 | P10: 19268063 | Q10: 17419950 | R10: 17278138 | S10: 22017450 | T10: 24361863 | U10: 25611320 | V10: 28863744 | W10: 42838778 | X10: 42221594 | Y10: 48331883 | Z10: 44825048 | AA10: 46008814 | AB10: 56340623 | AC10: 61278025 | AD10: 73815628 | AE10: 82643031 | AF10: 81955633 | AG10: 81955633 | AH10: 81955633
B11: Localiza ON | C11: PL | D11: 0 | E11: 0 | F11: 0 | G11: 0 | H11: 0 | I11: 10502002 | J11: 10565590 | K11: 191178 | L11: 194714 | M11: 195607 | N11: 256381 | O11: 334274 | P11: 378628 | Q11: 484121 | R11: 537256 | S11: 608685 | T11: 898742 | U11: 1120583 | V11: 1324753 | W11: 1341208 | X11: 1655504 | Y11: 1941577 | Z11: 2196990 | AA11: 2600725 | AB11: 3094502 | AC11: 5447532 | AD11: 6052659 | AE11: 7617090 | AF11: 20559196 | AG11: 20559196 | AH11: 20559196
B12: Itausa PN | C12: PL | D12: 0 | E12: 0 | F12: 2433214 | G12: 2770442 | H12: 2984403 | I12: 10502002 | J12: 10565590 | K12: 5054694 | L12: 6389415 | M12: 7636181 | N12: 8879419 | O12: 9753844 | P12: 12842285 | Q12: 15675809 | R12: 16591945 | S12: 19785992 | T12: 26302000 | U12: 29341000 | V12: 30027000 | W12: 33131000 | X12: 39226000 | Y12: 44846000 | Z12: 47729000 | AA12: 53229000 | AB12: 55143000 | AC12: 55232000 | AD12: 57343000 | AE12: 65886000 | AF12: 72797000 | AG12: 72797000 | AH12: 72797000
B13: Weg ON | C13: PL | D13: 0 | E13: 0 | F13: 263772 | G13: 295142 | H13: 353278 | I13: 10502002 | J13: 10565590 | K13: 573648 | L13: 693651 | M13: 861426 | N13: 1162002 | O13: 1371463 | P13: 1552724 | Q13: 1829174 | R13: 2178580 | S13: 2362787 | T13: 3454607 | U13: 3800112 | V13: 4060349 | W13: 4557772 | X13: 5056385 | Y13: 6029380 | Z13: 5962874 | AA13: 6720926 | AB13: 7714274 | AC13: 8717247 | AD13: 11563165 | AE13: 13604971 | AF13: 14834795 | AG13: 14834795 | AH13: 14834795
B14: Btgp Banco UNT | C14: PL | D14: 0 | E14: 0 | F14: 0 | G14: 0 | H14: 0 | I14: 10502002 | J14: 10565590 | K14: 0 | L14: 0 | M14: 0 | N14: 0 | O14: 0 | P14: 1200481 | Q14: 3829206 | R14: 3865215 | S14: 3244500 | T14: 5537682 | U14: 6339762 | V14: 10101467 | W14: 12127824 | X14: 14733327 | Y14: 19713264 | Z14: 17727219 | AA14: 18527813 | AB14: 18844934 | AC14: 21386635 | AD14: 26680655 | AE14: 37379747 | AF14: 42371767 | AG14: 42371767 | AH14: 42371767
... B25: BBSeguridade ON | C25: PL | D25: 0 | E25: 0 | F25: 0 | G25: 0 | H25: 0 | I25: 10502002 | J25: 10565590 | K25: 0 | L25: 0 | M25: 0 | N25: 0 | O25: 0 | P25: 0 | Q25: 0 | R25: 0 | S25: 0 | T25: 3248163 | U25: 5015683 | V25: 5638374 | W25: 6941273 | X25: 7923984 | Y25: 7580768 | Z25: 8289065 | AA25: 8898470 | AB25: 6830385 | AC25: 5248754 | AD25: 6389605 | AE25: 7281416 | AF25: 7596101 | AG25: 7596101 | AH25: 7596101
C26: Média | F26: =+ AVERAGEIF(F2:F25, "<>",F2:F25) -> 5526738.2 | G26: =+ AVERAGEIF(G2:G25, "<>",G2:G25) -> 5793103 | H26: =+ AVERAGEIF(H2:H25, "<>",H2:H25) -> 5880635.8 | I26: =+ AVERAGEIF(I2:I25, "<>",I2:I25) -> 10502002 | J26: =+ AVERAGEIF(J2:J25, "<>",J2:J25) -> 10565590 | K26: =+ AVERAGEIF(K2:K25, "<>",K2:K25) -> 7376539 | L26: =+ AVERAGEIF(L2:L25, "<>",L2:L25) -> 8263626.3 | M26: =+ AVERAGEIF(M2:M25, "<>",M2:M25) -> 10191029 | ... AH26: =+ AVERAGEIF(AH2:AH25, "<>",AH2:AH25) -> 83785578
B29: Ação | C29: Ano | F29: 1996 | G29: 1997 | H29: 1998 | I29: 1999 | J29: 2000 | K29: 2001 | L29: 2002 | M29: 2003 | N29: 2004 | O29: 2005 | P29: 2006 | Q29: 2007 | R29: 2008 | S29: 2009 | T29: 2010 | U29: 2011 | V29: 2012 | W29: 2013 | X29: 2014 | Y29: 2015 | Z29: 2016 | AA29: 2017 | AB29: 2018 | AC29: 2019 | AD29: 2020 | AE29: 2021 | AF29: 2022 | AG29: 2023 | AH29: 2024
B30: {=_xlfn.VSTACK(VALE3:BBSE3!L23:AR23)} -> Vale ON | C30: PL com inflação (corrigido) | D30: 0 | E30: 0 | F30: 11164498 | G30: 11063117 | H30: 11466967 | I30: 13435988 | J30: 14417612 | K30: 17001158 | L30: 20801691 | M30: 25767337 | N30: 31809885 | O30: 40202076 | P30: 56388336 | Q30: 78751026 | R30: 1.2539309e+08 | S30: 1.3076348e+08 | T30: 1.5726317e+08 | U30: 2.0273903e+08 | V30: 2.2375976e+08 | W30: 2.3622201e+08 | X30: 2.5341718e+08 | Y30: 2.5529423e+08 | Z30: 2.581756e+08 | AA30: 2.7538584e+08 | AB30: 3.1226731e+08 | AC30: 3.155574e+08 | AD30: 3.4572507e+08 | AE30: 3.7461108e+08 | AF30: 3.7190996e+08 | AG30: 3.7124358e+08 | AH30: 3.8230659e+08
B31: Petrobras PN | C31: PL com inflação (corrigido) | D31: 0 | E31: 0 | F31: 21155434 | G31: 23019304 | H31: 23938592 | I31: 14785402 | J31: 16583938 | K31: 37619942 | L31: 48971623 | M31: 70849502 | N31: 91241075 | O31: 1.1471972e+08 | P31: 1.3679001e+08 | Q31: 1.6026724e+08 | R31: 1.9752227e+08 | S31: 2.2968686e+08 | T31: 3.991181e+08 | U31: 4.5488379e+08 | V31: 4.9526511e+08 | W31: 5.4145816e+08 | X31: 5.4493418e+08 | Y31: 5.3051014e+08 | Z31: 5.4202679e+08 | AA31: 5.5661961e+08 | AB31: 5.9681515e+08 | AC31: 6.5087153e+08 | AD31: 6.7437628e+08 | AE31: 8.0201029e+08 | AF31: 7.807331e+08 | AG31: 7.7677157e+08 | AH31: 7.8466105e+08
B32: ItauUnibanco PN | C32: PL com inflação (corrigido) | D32: 0 | E32: 0 | F32: 4028175.1 | G32: 4455594.5 | H32: 4869124.3 | I32: 10861856 | J32: 10938006 | K32: 7974448.9 | L32: 9548584 | M32: 12266988 | N32: 14037372 | O32: 15102739 | P32: 22387683 | Q32: 27024164 | R32: 40911335 | S32: 46962032 | T32: 56090870 | U32: 65288936 | V32: 66569660 | W32: 71511996 | X32: 84097239 | Y32: 90651134 | Z32: 95795411 | AA32: 1.037297e+08 | AB32: 1.0485963e+08 | AC32: 1.0091099e+08 | AD32: 1.0004476e+08 | AE32: 99717843 | AF32: 1.1044805e+08 | AG32: 1.0427254e+08 | AH32: 1.0975801e+08
B33: Petrobras ON | C33: PL com inflação (corrigido) | D33: 0 | E33: 0 | F33: 21155434 | G33: 23019304 | H33: 23938592 | I33: 14785402 | J33: 16583938 | K33: 37619942 | L33: 48971623 | M33: 70849502 | N33: 91241075 | O33: 1.1471972e+08 | P33: 1.3679001e+08 | Q33: 1.6026724e+08 | R33: 1.9752227e+08 | S33: 2.2968686e+08 | T33: 3.991181e+08 | U33: 4.5488379e+08 | V33: 4.9526511e+08 | W33: 5.4145816e+08 | X33: 5.4493418e+08 | Y33: 5.3051014e+08 | Z33: 5.4202679e+08 | AA33: 5.5661961e+08 | AB33: 5.9681515e+08 | AC33: 6.5087153e+08 | AD33: 6.7437628e+08 | AE33: 8.0201029e+08 | AF33: 7.807331e+08 | AG33: 7.7677157e+08 | AH33: 7.8466105e+08
B34: Eletrobras ON | C34: PL com inflação (corrigido) | D34: 0 | E34: 0 | F34: 64925360 | G34: 69928029 | H34: 68211560 | I34: 24447571 | J34: 27298922 | K34: 85260527 | L34: 97665125 | M34: 1.0454686e+08 | N34: 1.080112e+08 | O34: 1.1026447e+08 | P34: 1.025269e+08 | Q34: 95391541 | R34: 92114745 | S34: 68521262 | T34: 47675567 | U34: 35805200 | V34: 2637032.8 | W34: -32052778 | X34: -67786337 | Y34: -1.2378093e+08 | Z34: -1.7184783e+08 | AA34: -2.2810743e+08 | AB34: -2.729879e+08 | AC34: -3.207797e+08 | AD34: -3.8976153e+08 | AE34: -4.8442989e+08 | AF34: -5.4706696e+08 | AG34: -6.5056322e+08 | AH34: -7.578855e+08
B35: Bradesco PN | C35: PL com inflação (corrigido) | D35: 0 | E35: 0 | F35: 5606620.7 | G35: 5780322.9 | H35: 6509130.5 | I35: 10807433 | J35: 10912936 | K35: 10205271 | L35: 11530327 | M35: 14301052 | N35: 15882432 | O35: 19814400 | P35: 24593456 | Q35: 29860298 | R35: 33301897 | S35: 40185665 | T35: 45827874 | U35: 52614551 | V35: 66093484 | W35: 65838816 | X35: 75039150 | Y35: 79976777 | Z35: 88995363 | AA35: 96704309 | AB35: 1.0498547e+08 | AC35: 1.149309e+08 | AD35: 1.2121317e+08 | AE35: 1.1925955e+08 | AF35: 1.2262808e+08 | AG35: 1.1839976e+08 | AH35: 1.2318718e+08
B36: B3 ON | C36: PL com inflação (corrigido) | D36: 0 | E36: 0 | F36: 0 | G36: 0 | H36: 0 | I36: 10502002 | J36: 10565590 | K36: 0 | L36: 0 | M36: 0 | N36: 823993.82 | O36: 869679.23 | P36: 1077441.3 | Q36: 1371413 | R36: 19316634 | S36: 19744636 | T36: 19935057 | U36: 20863434 | V36: 21181358 | W36: 22059752 | X36: 21970681 | Y36: 21668771 | Z36: 22240201 | AA36: 27356734 | AB36: 28789125 | AC36: 28765813 | AD36: 27396391 | AE36: 25201967 | AF36: 21927083 | AG36: 20706399 | AH36: 22161067
B37: Brasil ON | C37: PL com inflação (corrigido) | D37: 0 | E37: 0 | F37: 5797984.4 | G37: 6294194.5 | H37: 6898381.6 | I37: 10956586 | J37: 11097610 | K37: 9404572.1 | L37: 10164683 | M37: 13245361 | N37: 15118350 | O37: 17592857 | P37: 20953253 | Q37: 23932062 | R37: 29034777 | S37: 34393120 | T37: 47877865 | U37: 54445011 | V37: 60724462 | W37: 63335935 | X37: 69611519 | Y37: 67255720 | Z37: 72681320 | AA37: 81163060 | AB37: 81521988 | AC37: 82384656 | AD37: 95849234 | AE37: 1.070261e+08 | AF37: 1.1988437e+08 | AG37: 1.1402082e+08 | AH37: 1.1186519e+08
B38: Ambev S/A ON | C38: PL com inflação (corrigido) | D38: 0 | E38: 0 | F38: 1419786.5 | G38: 1595979.7 | H38: 1670318.5 | I38: 10990002 | J38: 11207206 | K38: 4198963.6 | L38: 5375578.1 | M38: 5798757.4 | N38: 18638351 | O38: 21447480 | P38: 20445564 | Q38: 18251735 | R38: 17829032 | S38: 22001852 | T38: 24385636 | U38: 26286238 | V38: 28629992 | W38: 43135341 | X38: 41142523 | Y38: 44848618 | Z38: 37631933 | AA38: 34823271 | AB38: 42919025 | AC38: 43722305 | AD38: 50380457 | AE38: 51988126 | AF38: 43347910 | AG38: 34704747 | AH38: 42181037
B39: Localiza ON | C39: PL com inflação (corrigido) | D39: 0 | E39: 0 | F39: 0 | G39: 0 | H39: 0 | I39: 10502002 | J39: 10565826 | K39: 192216.95 | L39: 197660.81 | M39: 199561.55 | N39: 283173.11 | O39: 403518.97 | P39: 469797.54 | Q39: 634732.9 | R39: 785262.42 | S39: 933796.48 | T39: 1364460.1 | U39: 1781396.6 | V39: 2151432.2 | W39: 2361391.3 | X39: 2903699.1 | Y39: 3353129.5 | Z39: 3670978.1 | AA39: 4043641.7 | AB39: 4809992.4 | AC39: 7535171.7 | AD39: 8074497.3 | AE39: 9960906.6 | AF39: 23664530 | AG39: 24192639 | AH39: 25511591
B40: Itausa PN | C40: PL com inflação (corrigido) | D40: 0 | E40: 0 | F40: 2722904.1 | G40: 3194760.6 | H40: 3393195.9 | I40: 11165478 | J40: 11344521 | K40: 6016007.1 | L40: 7779137.9 | M40: 9221133.8 | N40: 10463836 | O40: 11104807 | P40: 13677792 | Q40: 16023359 | R40: 16527515 | S40: 19128472 | T40: 25107721 | U40: 27500728 | V40: 27136402 | W40: 28997733 | X40: 33616633 | Y40: 36993652 | Z40: 37001444 | AA40: 39563356 | AB40: 38277429 | AC40: 37041691 | AD40: 37013652 | AE40: 39826919 | AF40: 41107858 | AG40: 34773536 | AH40: 32022086
B41: Weg ON | C41: PL com inflação (corrigido) | D41: 0 | E41: 0 | F41: 277794.59 | G41: 318763.31 | H41: 378984.47 | I41: 10547340 | J41: 10623971 | K41: 652157.11 | L41: 816345.57 | M41: 1023593.8 | N41: 1363579.8 | O41: 1604235 | P41: 1791774.2 | Q41: 2092127.2 | R41: 2495887.6 | S41: 2716222.9 | T41: 3916078.3 | U41: 4443697.5 | V41: 4854222.3 | W41: 5539393 | X41: 6227971.6 | Y41: 7315758.6 | Z41: 7226604.8 | AA41: 7896552.9 | AB41: 8958693.4 | AC41: 10013933 | AD41: 12756530 | AE41: 14829268 | AF41: 16021626 | AG41: 15899876 | AH41: 17632406
B42: Btgp Banco UNT | C42: PL com inflação (corrigido) | D42: 0 | E42: 0 | F42: 0 | G42: 0 | H42: 0 | I42: 10502002 | J42: 10565590 | K42: 0 | L42: 0 | M42: 0 | N42: 0 | O42: 0 | P42: 1200481 | Q42: 3830280.7 | R42: 3868283 | S42: 3249096.7 | T42: 5543571.7 | U42: 6348108.4 | V42: 10111578 | W42: 12145031 | X42: 14758935 | Y42: 19732456 | Z42: 17702354 | AA42: 18581955 | AB42: 18904281 | AC42: 21452474 | AD42: 26683421 | AE42: 37241134 | AF42: 42515939 | AG42: 42760004 | AH42: 43759707
... B53: BBSeguridade ON | C53: PL com inflação (corrigido) | D53: 0 | E53: 0 | F53: 0 | G53: 0 | H53: 0 | I53: 10502002 | J53: 10565590 | K53: 0 | L53: 0 | M53: 0 | N53: 0 | O53: 0 | P53: 0 | Q53: 0 | R53: 0 | S53: 0 | T53: 3248163 | U53: 5015683 | V53: 5638374 | W53: 6941273 | X53: 8269197.3 | Y53: 8534905.5 | Z53: 9337819.4 | AA53: 10020151 | AB53: 8031609.9 | AC53: 6875207.8 | AD53: 8349580.9 | AE53: 9275488.1 | AF53: 9908159.3 | AG53: 10185937 | AH53: 13158220
C54: Média | F54: =+ AVERAGEIF(F30:F53, "<>",F30:F53) -> 5940284 | G54: =+ AVERAGEIF(G30:G53, "<>",G30:G53) -> 6453370.1 | H54: =+ AVERAGEIF(H30:H53, "<>",H30:H53) -> 6563084.5 | I54: =+ AVERAGEIF(I30:I53, "<>",I30:I53) -> 11710396 | J54: =+ AVERAGEIF(J30:J53, "<>",J30:J53) -> 12108700 | K54: =+ AVERAGEIF(K30:K53, "<>",K30:K53) -> 9431434.2 | L54: =+ AVERAGEIF(L30:L53, "<>",L30:L53) -> 11497309 | M54: =+ AVERAGEIF(M30:M53, "<>",M30:M53) -> 14428627 | ... AH54: =+ AVERAGEIF(AH30:AH53, "<>",AH30:AH53) -> 84311119
B57: Ação | C57: Ano | F57: 1996 | G57: 1997 | H57: 1998 | I57: 1999 | J57: 2000 | K57: 2001 | L57: 2002 | M57: 2003 | N57: 2004 | O57: 2005 | P57: 2006 | Q57: 2007 | R57: 2008 | S57: 2009 | T57: 2010 | U57: 2011 | V57: 2012 | W57: 2013 | X57: 2014 | Y57: 2015 | Z57: 2016 | AA57: 2017 | AB57: 2018 | AC57: 2019 | AD57: 2020 | AE57: 2021 | AF57: 2022 | AG57: 2023 | AH57: 2024
B58: {=_xlfn.VSTACK(VALE3:BBSE3!L24:AR24)} -> Vale ON | C58: Valor de Mercado | D58: 0 | E58: 0 | F58: 9288841 | G58: 8125005.7 | H58: 4699923.1 | I58: 17428088 | J58: 16748049 | K58: 20187452 | L58: 38788909 | M58: 61970724 | N58: 82221308 | O58: 1.0508549e+08 | P58: 1.4484353e+08 | Q58: 2.7043777e+08 | R58: 1.3664159e+08 | S58: 2.432036e+08 | T58: 2.7500644e+08 | U58: 1.9794638e+08 | V58: 2.1511025e+08 | W58: 1.7816325e+08 | X58: 1.0763695e+08 | Y58: 61678209 | Z58: 1.277342e+08 | AA58: 2.0924861e+08 | AB58: 2.6143921e+08 | AC58: 2.7333748e+08 | AD58: 448610718 | AE58: 3.7729654e+08 | AF58: 3.9845597e+08 | AG58: 2.8269717e+08 | AH58: 2.1980911e+08
B59: Petrobras PN | C59: Valor de Mercado | D59: 0 | E59: 0 | F59: 15406641 | G59: 23527637 | H59: 10884365 | I59: 17428088 | J59: 16748049 | K59: 56404006 | L59: 54453901 | M59: 88658597 | N59: 1.1245814e+08 | O59: 1.7139064e+08 | P59: 2.2839733e+08 | Q59: 4.2992295e+08 | R59: 2.2399096e+08 | S59: 3.4708465e+08 | T59: 3.8024672e+08 | U59: 2.9156435e+08 | V59: 2.5485186e+08 | W59: 2.1468773e+08 | X59: 1.275056e+08 | Y59: 1.0131552e+08 | Z59: 2.0937755e+08 | AA59: 2.1604479e+08 | AB59: 316085347 | AC59: 4.0721885e+08 | AD59: 3.7346819e+08 | AE59: 3.8785255e+08 | AF59: 3.4592843e+08 | AG59: 3.7510234e+08 | AH59: 4.5431721e+08
B60: ItauUnibanco PN | C60: Valor de Mercado | D60: 0 | E60: 0 | F60: 5287458.4 | G60: 6187454.7 | H60: 6778330.9 | I60: 17428088 | J60: 16748049 | K60: 19572441 | L60: 17790256 | M60: 29935542 | N60: 42205297 | O60: 56543891 | P60: 84767712 | Q60: 1.0593022e+08 | R60: 96984165 | S60: 1.5441075e+08 | T60: 1.5966602e+08 | U60: 1.3738526e+08 | V60: 1.4574161e+08 | W60: 1.5061071e+08 | X60: 1.8305103e+08 | Y60: 1.5048804e+08 | Z60: 2.07453e+08 | AA60: 2.5900295e+08 | AB60: 3.1791001e+08 | AC60: 3.3627712e+08 | AD60: 2.9029441e+08 | AE60: 1.9549366e+08 | AF60: 2.2942838e+08 | AG60: 2.4301105e+08 | AH60: 2.3889635e+08
B61: Petrobras ON | C61: Valor de Mercado | D61: 0 | E61: 0 | F61: 15406641 | G61: 23527637 | H61: 10884365 | I61: 17428088 | J61: 16748049 | K61: 56404006 | L61: 54453901 | M61: 88658597 | N61: 1.1245814e+08 | O61: 1.7139064e+08 | P61: 2.2839733e+08 | Q61: 4.2992295e+08 | R61: 2.2399096e+08 | S61: 3.4708465e+08 | T61: 3.8024672e+08 | U61: 2.9156435e+08 | V61: 2.5485186e+08 | W61: 2.1468773e+08 | X61: 1.275056e+08 | Y61: 1.0131552e+08 | Z61: 2.0937755e+08 | AA61: 2.1604479e+08 | AB61: 316085347 | AC61: 4.0721885e+08 | AD61: 3.7346819e+08 | AE61: 3.8785255e+08 | AF61: 3.4592843e+08 | AG61: 3.8138493e+08 | AH61: 4.5648526e+08
B62: Eletrobras ON | C62: Valor de Mercado | D62: 0 | E62: 0 | F62: 20113082 | G62: 29958876 | H62: 11384030 | I62: 17428088 | J62: 16748049 | K62: 16908118 | L62: 12671298 | M62: 25788403 | N62: 20753914 | O62: 21640780 | P62: 28495223 | Q62: 26809962 | R62: 28927983 | S62: 40100342 | T62: 26211138 | U62: 26523902 | V62: 9664346.6 | W62: 9018232.4 | X62: 8477017.4 | Y62: 9034104.6 | Z62: 31671129 | AA62: 27051811 | AB62: 33820949 | AC62: 51246978 | AD62: 57626441 | AE62: 52310576 | AF62: 97238416 | AG62: 87944465 | AH62: 73332650
B63: Bradesco PN | C63: Valor de Mercado | D63: 0 | E63: 0 | F63: 6896759.4 | G63: 10327834 | H63: 6435282.8 | I63: 17428088 | J63: 16748049 | K63: 16545627 | L63: 14538427 | M63: 22699491 | N63: 28749554 | O63: 64733501 | P63: 84801127 | Q63: 1.0747445e+08 | R63: 65354163 | S63: 1.0328704e+08 | T63: 1.0975933e+08 | U63: 1.069705e+08 | V63: 1.3190797e+08 | W63: 1.2808456e+08 | X63: 1.4553583e+08 | Y63: 1.0004355e+08 | Z63: 1.6081275e+08 | AA63: 2.0052128e+08 | AB63: 2.4260582e+08 | AC63: 2.8207511e+08 | AD63: 2.2677847e+08 | AE63: 1.7147963e+08 | AF63: 1.5227397e+08 | AG63: 1.4797e+08 | AH63: 1.0747231e+08
B64: B3 ON | C64: Valor de Mercado | D64: 0 | E64: 0 | F64: 0 | G64: 0 | H64: 0 | I64: 17428088 | J64: 16748049 | K64: 0 | L64: 0 | M64: 0 | N64: 0 | O64: 0 | P64: 0 | Q64: 0 | R64: 11966905 | S64: 24558387 | T64: 25996365 | U64: 18894321 | V64: 27042015 | W64: 20943026 | X64: 17810559 | Y64: 19407014 | Z64: 29492588 | AA64: 46452052 | AB64: 54805426 | AC64: 87196861 | AD64: 1.2494436e+08 | AE64: 67351604 | AF64: 76043469 | AG64: 77216324 | AH64: 53464254
...

Sheet VALE3
A1: Vale ON | M1: Depreciação 2010 | N1: 0.0386
M3: VALE3
A4: Data | B4: Patrim Liq Em moeda orig em milhares consolid:sim* | C4: Lucro Liquido Em moeda orig em milhares no exercício consolid:sim* | D4: IntLiq Em moeda orig em milhares consolid:sim* | E4: Imobil Em moeda orig em milhares consolid:sim* | F4: Investm Em moeda orig em milhares consolid:sim* | G4: DivPag Em moeda orig em milhares no exercício consolid:sim* | H4: Div Yld (fim) 1 anos Em moeda orig | I4: Qtd Ações Outstanding da empresa em milhares | J4: PU ajust p/ prov Em moeda orig | K4: Valor Mercado da empresa Em moeda orig em milhares | M4: Ano | P4: 1996 | Q4: 1997 | R4: 1998 | S4: 1999 | T4: 2000 | U4: 2001 | V4: 2002 | W4: 2003 | X4: 2004 | Y4: 2005 | Z4: 2006 | AA4: 2007 | AB4: 2008 | AC4: 2009 | AD4: 2010 | AE4: 2011 | AF4: 2012 | AG4: 2013 | AH4: 2014 | AI4: 2015 | AJ4: 2016 | AK4: 2017 | AL4: 2018 | AM4: 2019 | AN4: 2020 | AO4: 2021 | AP4: 2022 | AQ4: 2023 | AR4: 2024
A5: 1995 | B5: 10519790 | C5: 328627 | D5: 0 | E5: 7575844 | F5: 0 | G5: =-107*1000 -> -107000 | H5: 0 | I5: 48569882 | J5: 0.59241276 | K5: 10489748 | M5: Inflação (IPCA) | P5: 0.0956 | Q5: 0.0522 | R5: 0.0166 | S5: 0.0894 | T5: 0.0597 | U5: 0.0767 | V5: 0.1253 | W5: 0.093 | X5: 0.076 | Y5: 0.0569 | Z5: 0.0314 | AA5: 0.0446 | AB5: 0.059 | AC5: 0.0431 | AD5: 0.0591 | AE5: 0.065 | AF5: 0.0584 | AG5: 0.0591 | AH5: 0.0641 | AI5: 0.1067 | AJ5: 0.0629 | AK5: 0.0295 | AL5: 0.0375 | AM5: 0.0431 | AN5: 0.0452 | AO5: 0.1006 | AP5: 0.0579 | AQ5: 0.0462 | AR5: 0.0483
A6: 1996 | B6: 10228870 | C6: 516990 | D6: 0 | E6: 11997968 | F6: 0 | G6: 0 | H6: 1.3881333 | I6: 376948 | J6: 0.52599139 | K6: 9288841 | M6: CMB (Efeito Imediato: Ano)
A7: 1997 | B7: 9472000 | C7: 756000 | D7: 0 | E7: 10830000 | F7: 0 | G7: 0 | H7: 3.9465876 | I7: 376948 | J7: 0.42351869 | K7: 8125005.7 | M7: CM Ativos não Monetários (inicial) | P7: =((D5+E5)*P5) -> 724250.69 | Q7: =((D6+E6+P7+P8)*Q5) -> 675133.72 | R7: =((D7+E7+Q7+P7+P8+Q8)*R5) -> 206010.61 | S7: =((D8+E8+R7+Q7+P7+SUM($P$8:R8))*S5) -> 1074369.5 | T7: =((D9+E9+S7+R7+Q7+P7+SUM($P$8:S8))*T5) -> 818090.92 | U7: =((D10+E10+T7+S7+R7+Q7+P7+SUM($P$8:T8))*U5) -> 1252893.1 | V7: =((D11+E11+U7+T7+S7+R7+Q7+P7+SUM($P$8:U8))*V5) -> 2230876.1 | W7: =((D12+E12+V7+U7+T7+S7+R7+Q7+P7+SUM($P$8:V8))*W5) -> 2147382 | X7: =((D13+E13+W7+V7+U7+T7+S7+R7+Q7+P7+SUM($P$8:W8))*X5) -> 2355491.6 | Y7: =((D14+E14+X7+W7+V7+U7+T7+S7+R7+Q7+P7+SUM($P$8:X8))*Y5) -> 2112071.8 | Z7: =((E14+F14+Y7+X7+W7+V7+U7+T7+S7+R7+Q7+P7+SUM($P$8:Y8))*Z5) -> 1239869.1 | AA7: =((D16+E16+Z7+Y7+X7+W7+V7+U7+T7+S7+R7+P7+Q7+SUM($P$8:Z8))*AA5) -> 4178135.2 | AB7: =((D17+E17+AA7+Z7+Y7+X7+W7+V7+U7+T7+S7+P7+Q7+R7+SUM($P$8:AA8))*AB5) -> 6639012.5 | AC7: =((D18+E18+AB7+AA7+Z7+Y7+X7+W7+V7+U7+T7+S7+R7+Q7+P7+SUM($P$8:AB8))*AC5) -> 5958419.2 | AD7: =((D19+E19+AC7+AB7+AA7+Z7+Y7+X7+W7+V7+U7+T7+S7+R7+Q7+P7+SUM($P$8:AC8))*AD5) -> 8804263.1 | AE7: =((D20+E20+AD7+AC7+AB7+AA7+Z7+Y7+X7+W7+V7+U7+T7+S7+R7+Q7+P7+SUM($P$8:AD8))*AE5) -> 12477260 | AF7: =((E20+F20+AE7+AD7+AC7+AB7+AA7+Z7+Y7+X7+W7+V7+U7+T7+S7+R7+Q7+P7+SUM($P$8:AE8))*AF5) -> 11158221 | AG7: =((D22+E22+AF7+AE7+AD7+AC7+AB7+AA7+Z7+Y7+X7+W7+V7+U7+T7+R7+S7+Q7+P7+SUM($P$8:AF8))*AG5) -> 15418542 | AH7: =((E22+F22+AG7+AF7+AE7+AD7+AC7+AB7+AA7+Z7+Y7+X7+W7+V7+U7+S7+T7+R7+Q7+P7+SUM($P$8:AG8))*AH5) -> 17369628 | AI7: =((F22+G22+AH7+AG7+AF7+AE7+AD7+AC7+AB7+AA7+Z7+Y7+X7+W7+V7+T7+U7+S7+R7+Q7+P7+SUM($P$8:AH8))*AI5) -> 11074344 | AJ7: =((G22+H22+AI7+AH7+AG7+AF7+AE7+AD7+AC7+AB7+AA7+Z7+Y7+X7+W7+U7+V7+T7+S7+R7+Q7+P7+SUM($P$8:AI8))*AJ5) -> 6426010.8 | AK7: =((H22+I22+AJ7+AI7+AH7+AG7+AF7+AE7+AD7+AC7+AB7+AA7+Z7+Y7+X7+V7+W7+U7+T7+S7+R7+Q7+P7+SUM($P$8:AJ8))*AK5) -> 3673187.3 | AL7: =((D27+E27+AK7+AJ7+AI7+AH7+AG7+AF7+AE7+AD7+AC7++AB7+AA7+Z7+Y7+X7+W7+V7+U7+T7+S7+R7+Q7+P7+SUM($P$8:AK8))*AL5) -> 12478547 | AM7: =((E27+F27+AL7+AK7+AJ7+AI7+AH7+AG7+AF7+AE7+AD7++AC7+AB7+AA7+Z7+Y7+X7+W7+V7+U7+T7+S7+R7+Q7+P7+SUM($P$8:AL8))*AM5) -> 14184658 | AN7: =((F27+G27+AM7+AL7+AK7+AJ7+AI7+AH7+AG7+AF7+AE7++AD7+AC7+AB7+AA7+Z7+Y7+X7+W7+V7+U7+T7+S7+R7+Q7+P7+SUM($P$8:AM8))*AN5) -> 7104168 | AO7: =((G27+H27+AN7+AM7+AL7+AK7+AJ7+AI7+AH7+AG7+AF7++AE7+AD7+AC7+AB7+AA7+Z7+Y7+X7+W7+V7+U7+T7+S7+R7+Q7+P7+SUM($P$8:AN8))*AO5) -> 15430221 | AP7: =((H27+I27+AO7+AN7+AM7+AL7+AK7+AJ7+AI7+AH7+AG7++AF7+AE7+AD7+AC7+AB7+AA7+Z7+Y7+X7+W7+V7+U7+T7+S7+R7+Q7+P7+SUM($P$8:AO8))*AP5) -> 10409859 | AQ7: =((I27+J27+AP7+AO7+AN7+AM7+AL7+AK7+AJ7+AI7+AH7++AG7+AF7+AE7+AD7+AC7+AB7+AA7+Z7+Y7+X7+W7+V7+U7+T7+S7+R7+Q7+P7+SUM($P$8:AP8))*AQ5) -> 8476556.6 | AR7: =((J27+K27+AQ7+AP7+AO7+AN7+AM7+AL7+AK7+AJ7+AI7++AH7+AG7+AF7+AE7+AD7+AC7+AB7+AA7+Z7+Y7+X7+W7+V7+U7+T7+S7+R7+Q7+P7+SUM($P$8:AQ8))*AR5) -> 18867766
A8: 1998 | B8: 9712283 | C8: 1029400 | D8: 0 | E8: 10236196 | F8: 0 | G8: 0 | H8: 22.48057 | I8: 384990 | J8: 0.25538657 | K8: 4699923.1 | M8: CM Ativos não Monetários (variação) | P8: =((D6+E6)-(D5+E5))*(P5^1/2) -> 211377.53 | Q8: =((D7+E7)-(D6+E6))*(Q5^1/2) -> -30483.965 | R8: =((D8+E8)-(D7+E7))*(R5^1/2) -> -4928.5732 | S8: =((D9+E9)-(D8+E8))*(S5^1/2) -> 26161.927 | T8: =((D10+E10)-(D9+E9))*(T5^1/2) -> 52564.686 | U8: =((D11+E11)-(D10+E10))*(U5^1/2) -> 7992.5619 | V8: =((D12+E12)-(D11+E11))*(V5^1/2) -> 180110.23 | W8: =((D13+E13)-(D12+E12))*(W5^1/2) -> 255752.19 | X8: =((D14+E14)-(D13+E13))*(X5^1/2) -> 138023.11 | Y8: =((D15+E15)-(D14+E14))*(Y5^1/2) -> 255191.81 | Z8: =((E15+F15)-(E14+F14))*(Z5^1/2) -> 140826.41 | AA8: =((D17+E17)-(D16+E16))*(AA5^1/2) -> 319946.82 | AB8: =((D18+E18)-(D17+E17))*(AB5^1/2) -> 546781.2 | AC8: =((D19+E19)-(D18+E18))*(AC5^1/2) -> 100572.26 | AD8: =((D20+E20)-(D19+E19))*(AD5^1/2) -> 981066.32 | AE8: =((D21+E21)-(D20+E20))*(AE5^1/2) -> 958655.52 | AF8: =((D22+E22)-(D21+E21))*(AF5^1/2) -> 421032.81 | AG8: =((D23+E23)-(D22+E22))*(AG5^1/2) -> 447014.94 | AH8: =((D24+E24)-(D23+E23))*(AH5^1/2) -> 583859.69 | AI8: =((D25+E25)-(D24+E24))*(AI5^1/2) -> 342902.54 | AJ8: =((D26+E26)-(D25+E25))*(AJ5^1/2) -> -913254.57 | AK8: =((D27+E27)-(D26+E26))*(AK5^1/2) -> 97625.471 | AL8: =((D28+E28)-(D27+E27))*(AL5^1/2) -> 163179.28 | AM8: =((D29+E29)-(D28+E28))*(AM5^1/2) -> 78835.072 | AN8: =((D30+E30)-(D29+E29))*(AN5^1/2) -> 907483.41 | AO8: =((D31+E31)-(D30+E30))*(AO5^1/2) -> 1113528.1 | AP8: =((D32+E32)-(D31+E31))*(AP5^1/2) -> -6724940.2 | AQ8: =((D32+E32)-(D31+E31))*(AQ5^1/2) -> -5366014.5 | AR8: =((E32+F32)-(E31+F31))*(AR5^1/2) -> -4575145
A9: 1999 | B9: 10502002 | C9: 1251199 | D9: 0 | E9: 10821474 | F9: 0 | G9: =-820*1000 -> -820000 | H9: 6.6190476 | I9: 388559.06 | J9: 1.0792524 | K9: 17428088 | M9: CM PL (inicial) | P9: =+B5*P5 -> 1005691.9 | Q9: =+(B6+P9+P10+P14)*Q5 -> 582786.81 | R9: =+(B7+Q9+P9+P10+Q10+P14+Q14)*R5 -> 182837.01 | S9: =+(B8+R9+Q9+P9+P10+Q10+R10+P14+Q14+R14)*S5 -> 1018419.3 | T9: =+(B9+S9+R9+Q9+P9+P10+Q10+R10+S10+P14+Q14+R14+S14)*T5 -> 788270.83 | U9: =+(B10+T9+S9+R9+Q9+P9+P10+Q10+R10+S10+T10+P14+Q14+R14+S14+T14)*U5 -> 1074592.5 | V9: =+(B11+U9+T9+S9+R9+Q9+P9+P10+Q10+R10+S10+T10+U10+P14+Q14+R14+S14+T14+U14)*V5 -> 2042193 | W9: =+(B12+V9+U9+T9+S9+R9+Q9+P9+P10+Q10+R10+S10+T10+U10+V10+P14+Q14+R14+S14+T14+U14+V14)*W5 -> 1808205.1 | X9: =+(B13+W9+V9+U9+T9+S9+R9+Q9+P9+P10+Q10+R10+S10+T10+U10+V10+W10+P14+Q14+R14+S14+T14+U14+V14+W14)*X5 -> 1798156.5 | Y9: =+(B14+X9+W9+V9+U9+T9+S9+R9+Q9+P9+P10+Q10+R10+S10+T10+U10+V10+W10+X10+P14+Q14+R14+S14+T14+U14+V14+W14+X14)*Y5 -> 1643248.8 | Z9: =+(B15+Y9+X9+W9+V9+U9+T9+S9+R9+Q9+P9+P10+Q10+R10+S10+T10+U10+V10+W10+X10+Y10+P14+Q14+R14+S14+T14+U14+V14+W14+X14+Y14)*Z5 -> 1145962.9 | AA9: =+(B16+Z9+Y9+X9+W9+V9+U9+T9+S9+R9+Q9+P9+P10+Q10+R10+S10+T10+U10+V10+W10+X10+Y10+Z10+P14+Q14+R14+S14+T14+U14+V14+W14+X14+Y14+Z14)*AA5 -> 2326995.5 | AB9: =+(B17+AA9+Z9+Y9+X9+W9+V9+U9+T9+S9+R9+Q9+P9+P10+Q10+R10+S10+T10+U10+V10+W10+X10+Y10+Z10+AA10+P14+Q14+R14+S14+T14+U14+V14+W14+X14+Y14+Z14+AA14)*AB5 -> 4352215.3 | AC9: =+(B18+AB9+AA9+Z9+Y9+X9+W9+V9+U9+T9+S9+R9+Q9+P9+P10+Q10+R10+S10+T10+U10+V10+W10+X10+Y10+Z10+AA10+AB10+P14+Q14+R14+S14+T14+U14+V14+W14+X14+Y14+Z14+AA14+AB14)*AC5 -> 5134367.3 | AD9: =+(B19+AC9+AB9+AA9+Z9+Y9+X9+W9+V9+U9+T9+S9+R9+Q9+P9+P10+Q10+R10+S10+T10+U10+V10+W10+X10+Y10+Z10+AA10+AB10+AC10+P14+Q14+R14+S14+T14+U14+V14+W14+X14+Y14+Z14+AA14+AB14+AC14)*AD5 -> 7283616.1 | AE9: =+(B20+AD9+AC9+AB9+AA9+Z9+Y9+X9+W9+V9+U9+T9+S9+R9+Q9+P9+P10+Q10+R10+S10+T10+U10+V10+W10+X10+Y10+Z10+AA10+AB10+AC10+AD10+P14+Q14+S14++R14+T14+U14+V14+W14+X14+Y14+Z14+AA14+AB14+AC14+AD14)*AE5 -> 9598671 | AF9: =+(B21+AE9+AD9+AC9+AB9+AA9+Z9+Y9+X9+W9+V9+U9+T9+S9+R9+Q9+P9+P10+Q10+R10+S10+T10+U10+V10+W10+X10+Y10+Z10+AA10+AB10+AC10+AD10+AE10+P14+Q14+R14+S14+T14+U14+V14+W14+X14+Y14+Z14+AA14+AB14+AC14+AD14+AE14)*AF5 -> 11108456 | AG9: =+(B22+AF9+AE9+AD9+AC9+AB9+AA9+Z9+Y9+X9+W9+V9+U9+T9+S9+R9+Q9+P9+P10+Q10+R10+S10+T10+U10+V10+W10+X10+Y10+Z10+AA10+AB10+AC10+AD10+AE10+AF10+P14+Q14+R14+S14+T14+U14+V14+W14+X14+Y14+Z14+AA14+AB14+AC14+AD14+AE14+AF14)*AG5 -> 12279386 | AH9: =+(B23+AG9+AF9+AE9+AD9+AC9+AB9+AA9+Z9+Y9+X9+W9+V9+U9+T9+S9+R9+Q9+P9+P10+Q10+R10+S10+T10+U10+V10+W10+X10+Y10+Z10+AA10+AB10+AC10+AD10+AE10+AF10+AG10+P14+Q14+R14+S14+T14+U14+V14+W14+X14+Y14+Z14+AA14+AB14+AC14+AD14+AE14+AF14+AG14)*AH5 -> 13846703 | AI9: =+(B24+AH9+AG9+AF9+AE9+AD9+AC9+AB9+AA9+Z9+Y9+X9+W9+V9+U9+T9+S9+R9+Q9+P9+P10+Q10+R10+S10+T10+U10+V10+W10+X10+Y10+Z10+AA10+AB10+AC10+AD10+AE10+AF10+AG10+AH10+P14+Q14+R14+S14+T14+U14+V14+W14+X14+Y14+Z14+AA14+AB14+AC14+AD14+AE14+AF14+AG14+AH14)*AI5 -> 24282734 | AJ9: =+(B25+AI9+AH9+AG9+AF9+AE9+AD9+AC9+AB9+AA9+Z9+Y9+X9+W9+V9+U9+T9+S9+R9+Q9+P9+P10++Q10+R10+S10+T10+U10+V10+W10+X10+Y10+Z10+AA10+AB10+AC10+AD10+AE10+AF10+AG10+AH10+AI10+P14+Q14+R14+S14+T14+U14+V14+W14+X14+Y14+Z14+AA14+AB14+AC14+AD14+AE14+AF14+AG14+AH14+AI14)*AJ5 -> 13714678 | AK9: =+(B26+AJ9+AI9+AH9+AG9+AF9+AE9+AD9+AC9+AB9+AA9+Z9+Y9+X9+W9+V9+U9+T9+S9+R9+Q9+P9+P10+Q10+R10+S10+T10+U10+V10+W10+X10+Y10+Z10+AA10+AB10+AC10+AD10+AE10+AF10+AG10+AH10+AI10+AJ10+P14+Q14+R14+S14+T14+U14+V14+W14+X14+Y14+Z14+AA14+AB14+AC14+AD14+AE14+AF14+AG14+AH14+AI14+AJ14)*AK5 -> 6286825.8 | AL9: =+(B27+AK9+AJ9+AI9+AH9+AG9+AF9+AE9+AD9+AC9+AB9+AA9+Z9+Y9+X9+W9+V9+U9+T9+S9+R9+Q9+P9+P10++Q10+R10+S10+T10+U10+V10+W10+X10+Y10+Z10+AA10+AB10+AC10+AD10+AE10+AF10+AG10+AH10+AI10+AJ10+AK10+P14+Q14+R14+S14+T14+U14+V14+W14+X14+Y14+Z14+AA14+AB14+AC14+AD14+AE14+AF14+AG14+AH14+AI14+AJ14+AK14)*AL5 -> 8492264.7 | AM9: =+(B28+AL9+AK9+AJ9+AI9+AH9+AG9+AF9+AE9+AD9+AC9+AB9+AA9+Z9+Y9+X9+W9+V9+U9+T9+S9+R9+Q9+P9+P10+Q10+R10+S10+T10+U10+V10+W10+X10+Y10+Z10+AA10+AB10+AC10+AD10+AE10+AF10+AG10+AH10+AI10+AJ10+AK10+AL10+P14+Q14+R14+S14+T14+U14+V14+W14+X14+Y14+Z14+AA14+AB14+AC14+AD14+AE14+AF14+AG14+AH14+AI14+AJ14+AK14+AL14)*AM5 -> 11137290 | AN9: =+(B29+AM9+AL9+AK9+AJ9+AI9+AH9+AG9+AF9+AE9+AD9+AC9+AB9+AA9+Z9+Y9+X9+W9+V9+U9+T9+S9+R9+Q9+P9+P10+Q10+R10+S10+T10+U10+V10+W10+X10+Y10+Z10+AA10+AB10+AC10+AD10+AE10+AF10+AG10+AH10+AI10+AJ10+AK10+AL10+AM10+P14+Q14+R14+S14+T14+U14+V14+W14+X14+Y14+Z14+AA14+AB14+AC14+AD14+AE14++AF14+AG14+AH14+AI14+AJ14+AK14+AL14+AM14)*AN5 -> 11552285 | AO9: =+(B30+AN9+AM9+AL9+AK9+AJ9+AI9+AH9+AG9+AF9+AE9+AD9+AC9+AB9+AA9+Z9+Y9+X9+W9+V9+U9+T9+S9+R9+Q9+P9+P10+Q10+R10+S10+T10+U10+V10+W10+X10+Y10+Z10+AA10+AB10+AC10+AD10+AE10+AF10+AG10+AH10+AI10+AJ10+AK10+AL10+AM10+AN10+P14+Q14+R14+S14+T14+U14+V14+W14+X14+Y14+Z14+AA14+AB14+AC14+AD14+AE14+AF14+AG14+AH14+AI14+AJ14+AK14+AL14+AM14+AN14)*AO5 -> 28045762 | AP9: =+(B31+AO9+AN9+AM9+AL9+AK9+AJ9+AI9+AH9+AG9+AF9+AE9+AD9+AC9+AB9+AA9+Z9+Y9+X9+W9+V9+U9+T9+S9+R9+Q9+P9+P10+Q10+R10+S10+T10+U10+V10+W10+X10+Y10+Z10+AA10+AB10+AC10+AD10+AE10+AF10+AG10+AH10+AI10+AJ10+AK10+AL10+AM10+AN10+AO10+P14+Q14+R14+S14+T14+U14+V14+W14+X14+Y14+Z14+AA14+AB14+AC14+AD14+AE14+AF14+AG14+AH14+AI14+AJ14+AK14+AL14+AM14+AN14+AO14)*AP5 -> 16882537 | AQ9: =+(B32+AP9+AO9+AN9+AM9+AL9+AK9+AJ9+AI9+AH9+AG9+AF9+AE9+AD9+AC9+AB9+AA9+Z9+Y9+X9+W9+V9+U9+T9+S9+R9+Q9+P9+P10+P14+Q10+R10+S10+T10+U10+V10+W10+X10+Y10+Z10+AA10+AB10+AC10+AD10+AE10+AF10+AG10+AH10+AI10+AJ10+AK10+AL10+AM10+AN10+AO10+AP10+Q14+R14+S14+T14+U14+V14+W14+X14+Y14+Z14+AA14+AB14+AC14+AD14+AE14+AF14+AG14+AH14+AI14+AJ14+AK14+AL14+AM14+AN14+AO14+AP14)*AQ5 -> 5871325.9 | AR9: =+(+P9+Q9+P10+Q10+P14+Q14+B33+AQ9+AP9+AO9+AN9+AM9+AL9+AK9+AJ9+AI9+AH9+AG9+AF9+AE9+AD9+AC9+AB9+AA9+Z9+Y9+X9+W9+V9+U9+T9+S9+R9+R10+S10+T10+U10+V10+W10+X10+Y10+Z10+AA10+AB10+AC10+AD10+AE10+AF10+AG10+AH10+AI10+AJ10+AK10+AL10+AM10+AN10+AO10+AP10+AQ10+R14+S14+T14+U14+V14+W14+X14+Y14+Z14+AA14+AB14+AC14+AD14+AE14+AF14+AG14+AH14+AI14+AJ14+AK14+AL14+AM14+AN14+AO14+AP14+AQ14)*AR5 -> 5867239.5
A10: 2000 | B10: 10565590 | C10: 2132657 | D10: 0 | E10: 12582435 | F10: 0 | G10: =-450*1000 -> -450000 | H10: 0 | I10: 384893 | J10: 1.1948866 | K10: 16748049 | M10: CM PL (variação) | P10: =((B6-B5)*(P5^1/2)) -> -13905.976 | Q10: =((B7-B6)*(Q5^1/2)) -> -19754.307 | R10: =((B8-B7)*(R5^1/2)) -> 1994.3489 | S10: =((B9-B8)*(S5^1/2)) -> 35300.439 | T10: =((B10-B9)*(T5^1/2)) -> 1898.1018 | U10: =((B11-B10)*(U5^1/2)) -> 46057.315 | V10: =((B12-B11)*(V5^1/2)) -> 61644.843 | W10: =((B13-B12)*(W5^1/2)) -> 101791.06 | X10: =((B14-B13)*(X5^1/2)) -> 122730.84 | Y10: =((B15-B14)*(Y5^1/2)) -> 167365.6 | Z10: =((B16-B15)*(Z5^1/2)) -> 236232.08 | AA10: =((B17-B16)*(AA5^1/2)) -> 399854.72 | AB10: =((B18-B17)*(AB5^1/2)) -> 1157732.7 | AC10: =((B19-B18)*(AC5^1/2)) -> -11586.702 | AD10: =((B20-B19)*(AD5^1/2)) -> 484059.44 | AE10: =((B21-B20)*(AE5^1/2)) -> 1019115.3 | AF10: =((B22-B21)*(AF5^1/2)) -> 260253.53 | AG10: =((B23-B22)*(AG5^1/2)) -> -119452.42 | AH10: =((B24-B23)*(AH5^1/2)) -> -61892.524 | AI10: =((B25-B24)*(AI5^1/2)) -> -813825.76 | AJ10: =((B26-B25)*(AJ5^1/2)) -> -123274.38 | AK10: =((B27-B26)*(AK5^1/2)) -> 243625.91 | AL10: =((B28-B27)*(AL5^1/2)) -> 499595.47 | AM10: =((B29-B28)*(AM5^1/2)) -> -192276.13 | AN10: =((B30-B29)*(AN5^1/2)) -> 549285.75 | AO10: =((B31-B30)*(AO5^1/2)) -> 332886.46 | AP10: =((B32-B31)*(AP5^1/2)) -> -4531717.2 | AQ10: =((C32-C31)*(AQ5^1/2)) -> -2366364 | AR10: =((D32-D31)*(AR5^1/2)) -> -1044197.7
A11: 2001 | B11: 11766563 | C11: 3050710 | D11: 0 | E11: 12790846 | F11: 0 | G11: =-2269*1000 -> -2269000 | H11: 15.269231 | I11: 383844 | J11: 1.5793 | K11: 20187452 | M11: CMB (Efeito Mediato: Futuro)
